<?xml version="1.0"?>
<robot
  xmlns:controller="http://playerstage.sourceforge.net/gazebo/xmlschema/#controller"
  xmlns:interface="http://playerstage.sourceforge.net/gazebo/xmlschema/#interface"
  xmlns:sensor="http://playerstage.sourceforge.net/gazebo/xmlschema/#sensor"
  xmlns:xacro="http://www.ros.org/wiki/xacro">

  <xacro:arg name="collision_detector" default="fcl"/>
  <xacro:property name="collision_detector" value="$(arg collision_detector)"/>

  <xacro:include filename="$(find lwr_defs)/defs/util_defs.xml" />

  <xacro:property name="arm_elem_base_mass" value="2.0" />
  <xacro:property name="arm_elem_link_mass" value="2.0" />
  <xacro:property name="arm_elem_end_link_mass" value="2.0" />
  <xacro:property name="arm_elem_ball_link_mass" value="2.0" />
  <xacro:property name="arm_velocity_scale_factor" value="1" />

  <xacro:macro name="visual_marker_xz_simple" params="size pos_x pos_y pos_z">
    <visual name="white_box1">
      <origin xyz="${pos_x + 0.5*size} ${pos_y} ${pos_z - 0.5*size}" rpy="0 0 0" />
      <geometry><box size="${size} 0.005 ${size}" /></geometry>
      <material name="White" ><color rgba="1 1 1 1.0"/></material>
    </visual>
    <visual name="white_box2">
      <origin xyz="${pos_x - 0.5*size} ${pos_y} ${pos_z + 0.5*size}" rpy="0 0 0" />
      <geometry><box size="${size} 0.005 ${size}" /></geometry>
      <material name="White" ><color rgba="1 1 1 1.0"/></material>
    </visual>
    <visual name="black_box1">
      <origin xyz="${pos_x + 0.5*size} ${pos_y} ${pos_z + 0.5*size}" rpy="0 0 0" />
      <geometry><box size="${size} 0.005 ${size}" /></geometry>
      <material name="Black" ><color rgba="0 0 0 1.0"/></material>
    </visual>
    <visual name="black_box2">
      <origin xyz="${pos_x - 0.5*size} ${pos_y} ${pos_z - 0.5*size}" rpy="0 0 0" />
      <geometry><box size="${size} 0.005 ${size}" /></geometry>
      <material name="Black" ><color rgba="0 0 0 1.0"/></material>
    </visual>
  </xacro:macro>

  <!-- right is either 1 (for right arm) or -1 (for left arm) - not used -->
  <xacro:macro name="kuka_lwr_arm" params="parent name right *origin">

    <joint name="${parent}_${name}_arm_base_joint" type="fixed">
      <xacro:insert_block name="origin" />
      <parent link="${parent}" />
      <child link="calib_${name}_arm_base_link" />
    </joint>

    <link name="calib_${name}_arm_base_link">
      <inertial>
        <mass value="${arm_elem_base_mass}" />
        <origin xyz="0 0 0.055" />
        <xacro:cylinder_inertia_def radius="0.06" length="0.11" mass="${arm_elem_base_mass}" />
      </inertial>
      <visual>
        <origin xyz="0 0 0" rpy="0 0 0" />
        <geometry>
          <mesh filename="package://lwr_defs/meshes/lwr/base_simplified.STL" />
        </geometry>
        <material name="Orange" >
          <color rgba="1 0.5 0 1.0"/>
        </material>
      </visual>
      <xacro:if value="${collision_detector == 'fcl'}">
        <collision>
          <origin xyz="0 0 0.055" rpy="0 0 ${M_PI}" />
          <geometry>
            <mesh filename="package://lwr_defs/meshes/lwr/convex/arm_base_convex.stl" />
          </geometry>
        </collision>
      </xacro:if>
      <self_collision_checking>
        <origin xyz="0 0 0.055" rpy="0 0 ${M_PI}" />
        <geometry>
          <capsule radius="0.07" length="0.11" />
        </geometry>
      </self_collision_checking>
    </link>

    <joint name="${name}_arm_0_joint" type="revolute">
      <origin xyz="0 0 0.11" rpy="0 0 0" />
      <axis xyz="0 0 1" />
      <limit lower="${-170 * M_PI / 180}" upper="${170 * M_PI / 180}"
             effort="204" velocity="${arm_velocity_scale_factor * 110 * M_PI / 180}" />
      <dynamics damping="1.0" />
      <parent link="calib_${name}_arm_base_link" />
      <child link="${name}_arm_1_link" />
    </joint>

    <link name="${name}_arm_1_link">
      <inertial>
        <mass value="${arm_elem_link_mass}" />
        <origin xyz="0 -0.06 0.13" rpy="0 0 0" />
        <xacro:cuboid_inertia_def length="0.12" width="0.06" height="0.26" mass="${arm_elem_link_mass}" />
      </inertial>
      <visual>
        <origin xyz="0 0 -0.008" rpy="0 0 0" />
        <geometry>
          <mesh filename="package://lwr_defs/meshes/lwr/link_1_simplified.STL" />
        </geometry>
        <material name="Orange" >
          <color rgba="1 0.5 0 1.0"/>
        </material>
      </visual>
      <xacro:if value="${collision_detector == 'fcl'}">
        <collision>
          <origin xyz="0 0 0" rpy="0 0 0" />
          <geometry>
            <mesh filename="package://lwr_defs/meshes/lwr/convex/arm_segment_a_convex.stl" />
          </geometry>
        </collision>
      </xacro:if>
      <xacro:if value="${collision_detector == 'dart'}">
        <collision>
          <origin xyz="0 0 0.0335732996464" rpy="0 0 0"/>
          <geometry>
            <sphere radius="0.073"/>
          </geometry>
        </collision>
        <collision>
          <origin xyz="0 -0.0317075103521 0.193762481213" rpy="0 0 0"/>
          <geometry>
            <sphere radius="0.073"/>
          </geometry>
        </collision>
        <collision>
          <origin xyz="0 -0.0298463404179 0.115765154362" rpy="0 0 0"/>
          <geometry>
            <sphere radius="0.07"/>
          </geometry>
        </collision>
      </xacro:if>
      <self_collision_checking>
        <origin xyz="0 -0.015 0.1" rpy="0.2 0 0" />
        <geometry>
          <capsule radius="0.065" length="0.208" />
        </geometry>
      </self_collision_checking>
    </link>

    <joint name="${name}_arm_1_joint" type="revolute">
      <origin xyz="0 0 0.2005" rpy="0 0 0" />
      <axis xyz="0 1 0" />
      <limit lower="${-120 * M_PI / 180}" upper="${120 * M_PI / 180}"
             effort="306" velocity="${arm_velocity_scale_factor * 110 * M_PI / 180}" />
      <dynamics damping="1.0" />
      <parent link="${name}_arm_1_link" />
      <child link="${name}_arm_2_link" />
    </joint>

    <link name="${name}_arm_2_link">
      <inertial>
        <mass value="${arm_elem_link_mass}" />
        <origin xyz="0 0.06 0.07" rpy="0 0 0" />
        <xacro:cuboid_inertia_def length="0.12" width="0.06" height="0.260" mass="${arm_elem_link_mass}" />
      </inertial>
      <visual>
        <origin xyz="0 0 0.0" rpy="0 0 0" />
        <geometry>
          <mesh filename="package://lwr_defs/meshes/lwr/link_2_simplified.STL" />
        </geometry>
        <material name="Orange" >
          <color rgba="1 0.5 0 1.0"/>
        </material>
      </visual>
      <xacro:if value="${collision_detector == 'fcl'}">
        <collision>
          <origin xyz="0 0 0.2" rpy="${M_PI} 0 0" />
          <geometry>
            <mesh filename="package://lwr_defs/meshes/lwr/convex/arm_segment_b_convex.stl" />
          </geometry>
        </collision>
      </xacro:if>
      <xacro:if value="${collision_detector == 'dart'}">
        <collision>
          <origin xyz="0.0 0.0286570191383 0.00607386231422" rpy="0 0 0"/>
          <geometry>
            <sphere radius="0.074"/>
          </geometry>
        </collision>
        <collision>
          <origin xyz="0 0.00150628387928 0.159803435206" rpy="0 0 0"/>
          <geometry>
            <sphere radius="0.0685738921165"/>
          </geometry>
        </collision>
        <collision>
          <origin xyz="0 0.0197636336088 0.0641110464931" rpy="0 0 0"/>
          <geometry>
            <sphere radius="0.0695144832134"/>
          </geometry>
        </collision>
        <collision>
          <origin xyz="0 0.00988520681858 0.104531049728" rpy="0 0 0"/>
          <geometry>
            <sphere radius="0.0645631551743"/>
          </geometry>
        </collision>
      </xacro:if>
      <self_collision_checking>
        <origin xyz="0 0.015 0.1" rpy="0.200 0 0" />
        <geometry>
          <capsule radius="0.065" length="0.208" />
        </geometry>
      </self_collision_checking>
    </link>

    <joint name="${name}_arm_2_joint" type="revolute">
      <origin xyz="0 0 0.20" rpy="0 0 0" />
      <axis xyz="0 0 1" />
      <limit lower="${-170 * M_PI / 180}" upper="${170 * M_PI / 180}"
             effort="204" velocity="${arm_velocity_scale_factor * 130 * M_PI / 180}" />
      <dynamics damping="1.0" />
      <parent link="${name}_arm_2_link" />
      <child link="${name}_arm_3_link" />
    </joint>

    <link name="${name}_arm_3_link">
      <inertial>
        <mass value="${arm_elem_link_mass}" />
        <origin xyz="0 0.06 0.13" rpy="0 0 0" />
        <xacro:cuboid_inertia_def length="0.12" width="0.06" height="0.26" mass="${arm_elem_link_mass}" />
      </inertial>
      <visual>
        <origin xyz="0 0 -0.008" rpy="0 0 0" />
        <geometry>
          <mesh filename="package://lwr_defs/meshes/lwr/link_3_simplified.STL" />
        </geometry>
        <material name="Orange" >
          <color rgba="1 0.5 0 1.0"/>
        </material>
      </visual>
      <xacro:if value="${collision_detector == 'fcl'}">
        <collision>
          <origin xyz="0 0 0" rpy="0 0 ${M_PI}" />
          <geometry>
            <mesh filename="package://lwr_defs/meshes/lwr/convex/arm_segment_a_convex.stl" />
          </geometry>
        </collision>
      </xacro:if>
      <xacro:if value="${collision_detector == 'dart'}">
        <collision>
          <origin xyz="0 0.031416490674 0.197126507759" rpy="0 0 0"/>
          <geometry>
            <sphere radius="0.0721492171288"/>
          </geometry>
        </collision>
        <collision>
          <origin xyz="0 0 0.043976649642" rpy="0 0 0"/>
          <geometry>
            <sphere radius="0.0721492171288"/>
          </geometry>
        </collision>
        <collision>
          <origin xyz="0 0.0280563533306 0.144906491041" rpy="0 0 0"/>
          <geometry>
            <sphere radius="0.0647548139095"/>
          </geometry>
        </collision>
        <collision>
          <origin xyz="0 0.0112177282572 0.0975905060768" rpy="0 0 0"/>
          <geometry>
            <sphere radius="0.0647548139095"/>
          </geometry>
        </collision>
      </xacro:if>
      <self_collision_checking>
        <origin xyz="0 0.015 0.1" rpy="-0.2 0 0" />
        <geometry>
          <capsule radius="0.065" length="0.208" />
        </geometry>
      </self_collision_checking>
    </link>

    <joint name="${name}_arm_3_joint" type="revolute">
      <origin xyz="0 0 0.20" rpy="0 0 0" />
      <axis xyz="0 -1 0" />
      <limit lower="${-120 * M_PI / 180}" upper="${120 * M_PI / 180}"
             effort="306" velocity="${arm_velocity_scale_factor * 130 * M_PI / 180}" />
      <dynamics damping="1.0" />
      <parent link="${name}_arm_3_link" />
      <child link="${name}_arm_4_link" />
    </joint>

    <link name="${name}_arm_4_link">
      <inertial>
        <mass value="${arm_elem_link_mass}" />
        <origin xyz="0 -0.06 0.07" rpy="0 0 0" />
        <xacro:cuboid_inertia_def length="0.12" width="0.06" height="0.26" mass="${arm_elem_link_mass}" />
      </inertial>
      <visual>
        <origin xyz="0 0 0.0" rpy="0 0 0" />
        <geometry>
          <mesh filename="package://lwr_defs/meshes/lwr/link_4_simplified.STL" />
        </geometry>
        <material name="Orange" >
          <color rgba="1 0.5 0 1.0"/>
        </material>
      </visual>
      <xacro:if value="${collision_detector == 'fcl'}">
        <collision>
          <origin xyz="0 0 0.2" rpy="0 ${M_PI} 0" />
          <geometry>
            <mesh filename="package://lwr_defs/meshes/lwr/convex/arm_segment_b_convex.stl" />
          </geometry>
        </collision>
      </xacro:if>
      <xacro:if value="${collision_detector == 'dart'}">
        <collision>
          <origin xyz="0 -0.032630354166 0.00386007130146" rpy="0 0 0"/>
          <geometry>
            <sphere radius="0.0728814601898"/>
          </geometry>
        </collision>
        <collision>
          <origin xyz="0 0 0.161616057158" rpy="0 0 0"/>
          <geometry>
            <sphere radius="0.0689925551414"/>
          </geometry>
        </collision>
        <collision>
          <origin xyz="0 -0.0249666124582 0.0531955659389" rpy="0 0 0"/>
          <geometry>
            <sphere radius="0.066763907671"/>
          </geometry>
        </collision>
        <collision>
          <origin xyz="0 -0.0114624202251 0.101935714483" rpy="0 0 0"/>
          <geometry>
            <sphere radius="0.066763907671"/>
          </geometry>
        </collision>
      </xacro:if>
      <self_collision_checking>
        <origin xyz="0 -0.015 0.1" rpy="-0.2 0 0" />
        <geometry>
          <capsule radius="0.065" length="0.208" />
        </geometry>
      </self_collision_checking>
    </link>

    <joint name="${name}_arm_4_joint" type="revolute">
      <origin xyz="0 0 0.20" rpy="0 0 0" />
      <axis xyz="0 0 1" />
      <limit lower="${-170 * M_PI / 180}" upper="${170 * M_PI / 180}"
             effort="204" velocity="${arm_velocity_scale_factor * 130 * M_PI / 180}" />
      <dynamics damping="1.0" />
      <parent link="${name}_arm_4_link" />
      <child link="${name}_arm_5_link" />
    </joint>

    <link name="${name}_arm_5_link">
      <inertial>
        <mass value="${arm_elem_link_mass}" />
        <origin xyz="0 0 0.124" rpy="0 0 0" />
        <xacro:cuboid_inertia_def length="0.12" width="0.06" height="0.248" mass="${arm_elem_link_mass}" />
      </inertial>
      <visual>
        <origin xyz="0 0 -0.008" rpy="0 0 0" />
        <geometry name="${name}_arm_5_geom">
          <mesh filename="package://lwr_defs/meshes/lwr/link_5_simplified.STL" />
        </geometry>
        <material name="Orange" >
          <color rgba="1 0.5 0 1.0"/>
        </material>
      </visual>
      <xacro:if value="${collision_detector == 'fcl'}">
        <collision>
          <origin xyz="0 0 0" rpy="0 0 0" />
          <geometry>
            <mesh filename="package://lwr_defs/meshes/lwr/convex/arm_segment_last_convex.stl" />
          </geometry>
        </collision>
      </xacro:if>
      <xacro:if value="${collision_detector == 'dart'}">
        <collision>
          <origin xyz="0 -0.0261997431517 0.187657207251" rpy="0 0 0"/>
          <geometry>
            <sphere radius="0.0741133093834"/>
          </geometry>
        </collision>
        <collision>
          <origin xyz="0 0 0.0451234206557" rpy="0 0 0"/>
          <geometry>
            <sphere radius="0.0698108077049"/>
          </geometry>
        </collision>
        <collision>
          <origin xyz="0 -0.0117612332106 0.0878629162908" rpy="0 0 0"/>
          <geometry>
            <sphere radius="0.0644374489784"/>
          </geometry>
        </collision>
        <collision>
          <origin xyz="0 -0.0240273177624 0.142486378551" rpy="0 0 0"/>
          <geometry>
            <sphere radius="0.0693661570549"/>
          </geometry>
        </collision>
      </xacro:if>
      <self_collision_checking>
        <origin xyz="0 -0.015 0.095" rpy="0.207 0 0" />
        <geometry>
          <capsule radius="0.065" length="0.198" />
        </geometry>
      </self_collision_checking>
    </link>

    <joint name="${name}_arm_5_joint" type="revolute">
      <origin xyz="0 0 0.19" rpy="0 0 0" />
      <axis xyz="0 1 0" />
      <limit lower="${-120 * M_PI / 180}" upper="${120 * M_PI / 180}"
             effort="306" velocity="${arm_velocity_scale_factor * 180 * M_PI / 180}" />
      <dynamics damping="1.0" />
      <parent link="${name}_arm_5_link" />
      <child link="${name}_arm_6_link" />
    </joint>

    <link name="${name}_arm_6_link" >
      <inertial>
        <mass value="0.2" />
        <origin xyz="0 0 0.0625" rpy="0 0 0" />
        <xacro:cuboid_inertia_def length="0.125" width="0.125" height="0.125" mass="0.2" />
      </inertial>
      <visual>
        <origin xyz="0 0 0" rpy="0 0 0" />
        <geometry>
          <mesh filename="package://lwr_defs/meshes/lwr/link_6_simplified.STL" />
        </geometry>
        <material name="Grey" >
          <color rgba="0.65 0.65 0.65 1.0"/>
        </material>
      </visual>
      <xacro:unless value="$(arg collision_model_no_hands)">
        <xacro:if value="${collision_detector == 'fcl'}">
          <collision>
            <origin xyz="0 0 0" rpy="0 0 0" />
            <geometry>
              <mesh filename="package://lwr_defs/meshes/lwr/convex/arm_wrist_convex.stl" />
            </geometry>
          </collision>
        </xacro:if>
        <xacro:if value="${collision_detector == 'dart'}">
          <collision>
            <origin xyz="0 0.00559139251709 0" rpy="0 0 0"/>
            <geometry>
              <sphere radius="0.0805927217007"/>
            </geometry>
          </collision>
        </xacro:if>
      </xacro:unless>
      <self_collision_checking>
        <origin xyz="0 0.01 0" rpy="0 0 0" />
        <geometry>
          <capsule radius="0.08" length="0" />
        </geometry>
      </self_collision_checking>
    </link>

    <joint name="${name}_arm_6_joint" type="revolute">
      <origin xyz="0 0 0.078" rpy="0 0 0" />
      <axis xyz="0 0 1" />
      <limit lower="${-170 * M_PI / 180}" upper="${170 * M_PI / 180}"
             effort="204" velocity="${arm_velocity_scale_factor * 180 * M_PI / 180}" />
      <dynamics damping="1.0" />
      <parent link="${name}_arm_6_link" />
      <child link="${name}_arm_7_link" />
    </joint>

    <link name="${name}_arm_7_link">
      <inertial>
        <mass value="0.002" />
        <origin xyz="0 0 0" />
        <xacro:cuboid_inertia_def length="1" width="1" height="1" mass="0.002" />
      </inertial>
      <visual>
        <origin xyz="0 0 0" rpy="0 0 0" />
        <geometry>
          <mesh filename="package://lwr_defs/meshes/lwr/link_7_simplified.STL" />
        </geometry>
        <material name="Grey" >
          <color rgba="0.65 0.65 0.65 1.0"/>
        </material>
      </visual>
    </link>

    <joint name="${name}_arm_ee_joint" type="fixed">
      <origin xyz="0 0 0" rpy="0 0 0"/>
      <parent link="${name}_arm_7_link"/>
      <child link="${name}_arm_ee_link"/>
    </joint>

    <link name="${name}_arm_ee_link">
      <inertial>
        <mass value="0"/>
        <origin rpy="0 0 0" xyz="0 0 0"/>
        <inertia ixx="0" ixy="0" ixz="0" iyy="0" iyz="0" izz="0"/>
      </inertial>
    </link>

    <gazebo reference="calib_${name}_arm_base_link">
      <turnGravityOff>false</turnGravityOff>
      <selfCollide>true</selfCollide>
      <material>Gazebo/Orange</material>
    </gazebo>
    <gazebo reference="${name}_arm_1_link">
      <turnGravityOff>false</turnGravityOff>
      <selfCollide>true</selfCollide>
      <material>Gazebo/Orange</material>
    </gazebo>
    <gazebo reference="${name}_arm_2_link">
      <turnGravityOff>false</turnGravityOff>
      <selfCollide>true</selfCollide>
      <material>Gazebo/Orange</material>
    </gazebo>
    <gazebo reference="${name}_arm_3_link">
      <turnGravityOff>false</turnGravityOff>
      <selfCollide>true</selfCollide>
      <material>Gazebo/Orange</material>
    </gazebo>
    <gazebo reference="${name}_arm_4_link">
      <turnGravityOff>false</turnGravityOff>
      <selfCollide>true</selfCollide>
      <material>Gazebo/Orange</material>
    </gazebo>
    <gazebo reference="${name}_arm_5_link">
      <turnGravityOff>false</turnGravityOff>
      <selfCollide>true</selfCollide>
      <material>Gazebo/Orange</material>
    </gazebo>
    <gazebo reference="${name}_arm_6_link">
      <turnGravityOff>false</turnGravityOff>
      <selfCollide>true</selfCollide>
      <material>Gazebo/Grey</material>
    </gazebo>
    <gazebo reference="${name}_arm_6_joint">
      <provideFeedback>true</provideFeedback>
    </gazebo>
    <gazebo reference="${name}_arm_7_link">
      <turnGravityOff>false</turnGravityOff>
      <selfCollide>true</selfCollide>
      <material>Gazebo/Grey</material>
    </gazebo>
    <!--
    <transmission name="${name}_arm_0_trans" type="SimpleTransmission">
      <actuator name="${name}_arm_0_motor" />
      <joint name="${name}_arm_0_joint" />
      <mechanicalReduction>1.0</mechanicalReduction>
    </transmission>
    <transmission name="${name}_arm_1_trans" type="SimpleTransmission">
      <actuator name="${name}_arm_1_motor" />
      <joint name="${name}_arm_1_joint" />
      <mechanicalReduction>1.0</mechanicalReduction>
    </transmission>
    <transmission name="${name}_arm_2_trans" type="SimpleTransmission">
      <actuator name="${name}_arm_2_motor" />
      <joint name="${name}_arm_2_joint" />
      <mechanicalReduction>1.0</mechanicalReduction>
    </transmission>
    <transmission name="${name}_arm_3_trans" type="SimpleTransmission">
      <actuator name="${name}_arm_3_motor" />
      <joint name="${name}_arm_3_joint" />
      <mechanicalReduction>1.0</mechanicalReduction>
    </transmission>
    <transmission name="${name}_arm_4_trans" type="SimpleTransmission">
      <actuator name="${name}_arm_4_motor" />
      <joint name="${name}_arm_4_joint" />
      <mechanicalReduction>1.0</mechanicalReduction>
    </transmission>
    <transmission name="${name}_arm_5_trans" type="SimpleTransmission">
      <actuator name="${name}_arm_5_motor" />
      <joint name="${name}_arm_5_joint" />
      <mechanicalReduction>1.0</mechanicalReduction>
    </transmission>
    <transmission name="${name}_arm_6_trans" type="SimpleTransmission">
      <actuator name="${name}_arm_6_motor" />
      <joint name="${name}_arm_6_joint" />
      <mechanicalReduction>1.0</mechanicalReduction>
    </transmission>
  -->
  </xacro:macro>
</robot>
