<?xml version="1.0"?>
<robot
  xmlns:controller="http://playerstage.sourceforge.net/gazebo/xmlschema/#controller"
  xmlns:interface="http://playerstage.sourceforge.net/gazebo/xmlschema/#interface"
  xmlns:sensor="http://playerstage.sourceforge.net/gazebo/xmlschema/#sensor"
  xmlns:xacro="http://www.ros.org/wiki/xacro">

  <xacro:include filename="$(find lwr_defs)/defs/util_defs.xml" />

  <xacro:property name="arm_elem_base_mass" value="2.0" />
  <xacro:property name="arm_elem_link_mass" value="2.0" />
  <xacro:property name="arm_elem_end_link_mass" value="2.0" />
  <xacro:property name="arm_elem_ball_link_mass" value="2.0" />
  <xacro:property name="arm_velocity_scale_factor" value="1" />

  <xacro:macro name="visual_marker_xz_simple" params="size pos_x pos_y pos_z">
    <visual name="white_box1">
      <origin xyz="${pos_x + 0.5*size} ${pos_y} ${pos_z - 0.5*size}" rpy="0 0 0" />
      <geometry><box size="${size} 0.005 ${size}" /></geometry>
      <material name="White" ><color rgba="1 1 1 1.0"/></material>
    </visual>
    <visual name="white_box2">
      <origin xyz="${pos_x - 0.5*size} ${pos_y} ${pos_z + 0.5*size}" rpy="0 0 0" />
      <geometry><box size="${size} 0.005 ${size}" /></geometry>
      <material name="White" ><color rgba="1 1 1 1.0"/></material>
    </visual>
    <visual name="black_box1">
      <origin xyz="${pos_x + 0.5*size} ${pos_y} ${pos_z + 0.5*size}" rpy="0 0 0" />
      <geometry><box size="${size} 0.005 ${size}" /></geometry>
      <material name="Black" ><color rgba="0 0 0 1.0"/></material>
    </visual>
    <visual name="black_box2">
      <origin xyz="${pos_x - 0.5*size} ${pos_y} ${pos_z - 0.5*size}" rpy="0 0 0" />
      <geometry><box size="${size} 0.005 ${size}" /></geometry>
      <material name="Black" ><color rgba="0 0 0 1.0"/></material>
    </visual>
  </xacro:macro>

  <!-- right is either 1 (for right arm) or -1 (for left arm) - not used -->
  <xacro:macro name="kuka_lwr_arm" params="parent name right *origin">

    <joint name="${parent}_${name}_arm_base_joint" type="fixed">
      <insert_block name="origin" />
      <parent link="${parent}" />
      <child link="calib_${name}_arm_base_link" />
    </joint>

    <link name="calib_${name}_arm_base_link">
      <inertial>
        <mass value="${arm_elem_base_mass}" />
        <origin xyz="0 0 0.055" />
        <cylinder_inertia_def radius="0.06" length="0.11" mass="${arm_elem_base_mass}" />
      </inertial>
      <visual>
        <origin xyz="0 0 0" rpy="0 0 0" />
        <geometry>
          <mesh filename="package://lwr_defs/meshes/lwr/base_simplified.STL" />
        </geometry>
        <material name="Orange" >
          <color rgba="1 0.5 0 1.0"/>
        </material>
      </visual>
      <collision>
        <origin xyz="0 0 0.055" rpy="0 0 ${M_PI}" />
        <geometry>
          <mesh filename="package://lwr_defs/meshes/lwr/convex/arm_base_convex.stl" />
        </geometry>
      </collision>
      <self_collision_checking>
        <origin xyz="0 0 0.055" rpy="0 0 ${M_PI}" />
        <geometry>
          <capsule radius="0.07" length="0.11" />
        </geometry>
      </self_collision_checking>
    </link>

    <joint name="${name}_arm_0_joint" type="revolute">
      <origin xyz="0 0 0.11" rpy="0 0 0" />
      <axis xyz="0 0 1" />
      <limit lower="${-170 * M_PI / 180}" upper="${170 * M_PI / 180}"
             effort="204" velocity="${arm_velocity_scale_factor * 110 * M_PI / 180}" />
      <dynamics damping="1.0" />
      <parent link="calib_${name}_arm_base_link" />
      <child link="${name}_arm_1_link" />
    </joint>

    <link name="${name}_arm_1_link">
      <inertial>
        <mass value="${arm_elem_link_mass}" />
        <origin xyz="0 -0.06 0.13" rpy="0 0 0" />
        <cuboid_inertia_def length="0.12" width="0.06" height="0.26" mass="${arm_elem_link_mass}" />
      </inertial>
      <visual>
        <origin xyz="0 0 -0.008" rpy="0 0 0" />
        <geometry>
          <mesh filename="package://lwr_defs/meshes/lwr/link_1_simplified.STL" />
        </geometry>
        <material name="Orange" >
          <color rgba="1 0.5 0 1.0"/>
        </material>
      </visual>
      <collision>
        <origin xyz="0 0 0" rpy="0 0 0" />
        <geometry>
          <mesh filename="package://lwr_defs/meshes/lwr/convex/arm_segment_a_convex.stl" />
        </geometry>
      </collision>
      <self_collision_checking>
        <origin xyz="0 -0.015 0.1" rpy="0.2 0 0" />
        <geometry>
          <capsule radius="0.065" length="0.208" />
        </geometry>
      </self_collision_checking>
    </link>

    <joint name="${name}_arm_1_joint" type="revolute">
      <origin xyz="0 0 0.2005" rpy="0 0 0" />
      <axis xyz="0 1 0" />
      <limit lower="${-120 * M_PI / 180}" upper="${120 * M_PI / 180}"
             effort="306" velocity="${arm_velocity_scale_factor * 110 * M_PI / 180}" />
      <dynamics damping="1.0" />
      <parent link="${name}_arm_1_link" />
      <child link="${name}_arm_2_link" />
    </joint>

    <link name="${name}_arm_2_link">
      <inertial>
        <mass value="${arm_elem_link_mass}" />
        <origin xyz="0 0.06 0.07" rpy="0 0 0" />
        <cuboid_inertia_def length="0.12" width="0.06" height="0.260" mass="${arm_elem_link_mass}" />
      </inertial>
      <visual>
        <origin xyz="0 0 0.0" rpy="0 0 0" />
        <geometry>
          <mesh filename="package://lwr_defs/meshes/lwr/link_2_simplified.STL" />
        </geometry>
        <material name="Orange" >
          <color rgba="1 0.5 0 1.0"/>
        </material>
      </visual>
      <collision>
        <origin xyz="0 0 0.2" rpy="${M_PI} 0 0" />
        <geometry>
          <mesh filename="package://lwr_defs/meshes/lwr/convex/arm_segment_b_convex.stl" />
        </geometry>
      </collision>
      <self_collision_checking>
        <origin xyz="0 0.015 0.1" rpy="0.200 0 0" />
        <geometry>
          <capsule radius="0.065" length="0.208" />
        </geometry>
      </self_collision_checking>
    </link>

    <joint name="${name}_arm_2_joint" type="revolute">
      <origin xyz="0 0 0.20" rpy="0 0 0" />
      <axis xyz="0 0 1" />
      <limit lower="${-170 * M_PI / 180}" upper="${170 * M_PI / 180}"
             effort="204" velocity="${arm_velocity_scale_factor * 130 * M_PI / 180}" />
      <dynamics damping="1.0" />
      <parent link="${name}_arm_2_link" />
      <child link="${name}_arm_3_link" />
    </joint>

    <link name="${name}_arm_3_link">
      <inertial>
        <mass value="${arm_elem_link_mass}" />
        <origin xyz="0 0.06 0.13" rpy="0 0 0" />
        <cuboid_inertia_def length="0.12" width="0.06" height="0.26" mass="${arm_elem_link_mass}" />
      </inertial>
      <visual>
        <origin xyz="0 0 -0.008" rpy="0 0 0" />
        <geometry>
          <mesh filename="package://lwr_defs/meshes/lwr/link_3_simplified.STL" />
        </geometry>
        <material name="Orange" >
          <color rgba="1 0.5 0 1.0"/>
        </material>
      </visual>
      <collision>
        <origin xyz="0 0 0" rpy="0 0 ${M_PI}" />
        <geometry>
          <mesh filename="package://lwr_defs/meshes/lwr/convex/arm_segment_a_convex.stl" />
        </geometry>
      </collision>
      <self_collision_checking>
        <origin xyz="0 0.015 0.1" rpy="-0.2 0 0" />
        <geometry>
          <capsule radius="0.065" length="0.208" />
        </geometry>
      </self_collision_checking>
      <visual_marker_xz_simple size="0.02" pos_x="0" pos_y="0.095" pos_z="0.2" />
    </link>
    <!--<visual_marker_xz parent="${name}_arm_3_link" size="0.02" pos_x="0" pos_y="0.095" pos_z="0.2" />-->

    <joint name="${name}_arm_3_joint" type="revolute">
      <origin xyz="0 0 0.20" rpy="0 0 0" />
      <axis xyz="0 -1 0" />
      <limit lower="${-120 * M_PI / 180}" upper="${120 * M_PI / 180}"
             effort="306" velocity="${arm_velocity_scale_factor * 130 * M_PI / 180}" />
      <dynamics damping="1.0" />
      <parent link="${name}_arm_3_link" />
      <child link="${name}_arm_4_link" />
    </joint>

    <link name="${name}_arm_4_link">
      <inertial>
        <mass value="${arm_elem_link_mass}" />
        <origin xyz="0 -0.06 0.07" rpy="0 0 0" />
        <cuboid_inertia_def length="0.12" width="0.06" height="0.26" mass="${arm_elem_link_mass}" />
      </inertial>
      <visual>
        <origin xyz="0 0 0.0" rpy="0 0 0" />
        <geometry>
          <mesh filename="package://lwr_defs/meshes/lwr/link_4_simplified.STL" />
        </geometry>
        <material name="Orange" >
          <color rgba="1 0.5 0 1.0"/>
        </material>
      </visual>
      <collision>
        <origin xyz="0 0 0.2" rpy="0 ${M_PI} 0" />
        <geometry>
          <mesh filename="package://lwr_defs/meshes/lwr/convex/arm_segment_b_convex.stl" />
        </geometry>
      </collision>
      <self_collision_checking>
        <origin xyz="0 -0.015 0.1" rpy="-0.2 0 0" />
        <geometry>
          <capsule radius="0.065" length="0.208" />
        </geometry>
      </self_collision_checking>
      <visual_marker_xz_simple size="0.02" pos_x="0" pos_y="-0.095" pos_z="0" />
    </link>
    <!--<visual_marker_xz parent="${name}_arm_4_link" size="0.02" pos_x="0" pos_y="-0.095" pos_z="0" />-->

    <joint name="${name}_arm_4_joint" type="revolute">
      <origin xyz="0 0 0.20" rpy="0 0 0" />
      <axis xyz="0 0 1" />
      <limit lower="${-170 * M_PI / 180}" upper="${170 * M_PI / 180}"
             effort="204" velocity="${arm_velocity_scale_factor * 130 * M_PI / 180}" />
      <dynamics damping="1.0" />
      <parent link="${name}_arm_4_link" />
      <child link="${name}_arm_5_link" />
    </joint>

    <link name="${name}_arm_5_link">
      <inertial>
        <mass value="${arm_elem_link_mass}" />
        <origin xyz="0 0 0.124" rpy="0 0 0" />
        <cuboid_inertia_def length="0.12" width="0.06" height="0.248" mass="${arm_elem_link_mass}" />
      </inertial>
      <visual>
        <origin xyz="0 0 -0.008" rpy="0 0 0" />
        <geometry name="${name}_arm_5_geom">
          <mesh filename="package://lwr_defs/meshes/lwr/link_5_simplified.STL" />
        </geometry>
        <material name="Green" >
          <color rgba="1 0.5 0 1.0"/>
        </material>
      </visual>
      <visual>
        <origin xyz="0 0 -0.008" rpy="0 0 0" />
        <geometry name="${name}_arm_5_geom">
          <mesh filename="package://lwr_defs/meshes/lwr/link_5_simplified.STL" />
        </geometry>
        <material name="Blue" >
          <color rgba="1 0.5 0 1.0"/>
        </material>
      </visual>
      <collision>
        <origin xyz="0 0 0" rpy="0 0 0" />
        <geometry>
          <mesh filename="package://lwr_defs/meshes/lwr/convex/arm_segment_last_convex.stl" />
        </geometry>
      </collision>
      <self_collision_checking>
        <origin xyz="0 -0.015 0.095" rpy="0.207 0 0" />
        <geometry>
          <capsule radius="0.065" length="0.198" />
        </geometry>
      </self_collision_checking>
      <visual_marker_xz_simple size="0.02" pos_x="0" pos_y="-0.095" pos_z="0.19" />
    </link>
    <!--<visual_marker_xz parent="${name}_arm_5_link" size="0.02" pos_x="0" pos_y="-0.095" pos_z="0.19" />-->

    <joint name="${name}_arm_5_joint" type="revolute">
      <origin xyz="0 0 0.19" rpy="0 0 0" />
      <axis xyz="0 1 0" />
      <limit lower="${-120 * M_PI / 180}" upper="${120 * M_PI / 180}"
             effort="306" velocity="${arm_velocity_scale_factor * 180 * M_PI / 180}" />
      <dynamics damping="1.0" />
      <parent link="${name}_arm_5_link" />
      <child link="${name}_arm_6_link" />
    </joint>

    <link name="${name}_arm_6_link" >
      <inertial>
        <mass value="0.2" />
        <origin xyz="0 0 0.0625" rpy="0 0 0" />
        <cuboid_inertia_def length="0.125" width="0.125" height="0.125" mass="0.2" />
      </inertial>
      <visual>
        <origin xyz="0 0 0" rpy="0 0 0" />
        <geometry>
          <mesh filename="package://lwr_defs/meshes/lwr/link_6_simplified.STL" />
        </geometry>
        <material name="Grey" >
          <color rgba="0.65 0.65 0.65 1.0"/>
        </material>
      </visual>
      <xacro:unless value="$(arg collision_model_no_hands)">
        <collision>
          <origin xyz="0 0 0" rpy="0 0 0" />
          <geometry>
            <mesh filename="package://lwr_defs/meshes/lwr/convex/arm_wrist_convex.stl" />
          </geometry>
        </collision>
      </xacro:unless>
      <self_collision_checking>
        <origin xyz="0 0.01 0" rpy="0 0 0" />
        <geometry>
          <capsule radius="0.08" length="0" />
        </geometry>
      </self_collision_checking>
      <visual_marker_xz_simple size="0.02" pos_x="0" pos_y="0.08" pos_z="0" />
    </link>
    <!--<visual_marker_xz parent="${name}_arm_6_link" size="0.02" pos_x="0" pos_y="0.08" pos_z="0" />-->

    <joint name="${name}_arm_6_joint" type="revolute">
      <origin xyz="0 0 0.078" rpy="0 0 0" />
      <axis xyz="0 0 1" />
      <limit lower="${-170 * M_PI / 180}" upper="${170 * M_PI / 180}"
             effort="204" velocity="${arm_velocity_scale_factor * 180 * M_PI / 180}" />
      <dynamics damping="1.0" />
      <parent link="${name}_arm_6_link" />
      <child link="${name}_arm_7_link" />
    </joint>

    <link name="${name}_arm_7_link">
      <inertial>
        <mass value="0.002" />
        <origin xyz="0 0 0" />
        <cuboid_inertia_def length="1" width="1" height="1" mass="0.002" />
      </inertial>
      <visual>
        <origin xyz="0 0 0" rpy="0 0 0" />
        <geometry>
          <mesh filename="package://lwr_defs/meshes/lwr/link_7_simplified.STL" />
        </geometry>
        <material name="Grey" >
          <color rgba="0.65 0.65 0.65 1.0"/>
        </material>
      </visual>
    </link>

    <gazebo reference="calib_${name}_arm_base_link">
      <turnGravityOff>false</turnGravityOff>
      <selfCollide>true</selfCollide>
      <material>Gazebo/Orange</material>
    </gazebo>
    <gazebo reference="${name}_arm_1_link">
      <turnGravityOff>false</turnGravityOff>
      <selfCollide>true</selfCollide>
      <material>Gazebo/Orange</material>
    </gazebo>
    <gazebo reference="${name}_arm_2_link">
      <turnGravityOff>false</turnGravityOff>
      <selfCollide>true</selfCollide>
      <material>Gazebo/Orange</material>
    </gazebo>
    <gazebo reference="${name}_arm_3_link">
      <turnGravityOff>false</turnGravityOff>
      <selfCollide>true</selfCollide>
      <material>Gazebo/Orange</material>
    </gazebo>
    <gazebo reference="${name}_arm_4_link">
      <turnGravityOff>false</turnGravityOff>
      <selfCollide>true</selfCollide>
      <material>Gazebo/Orange</material>
    </gazebo>
    <gazebo reference="${name}_arm_5_link">
      <turnGravityOff>false</turnGravityOff>
      <selfCollide>true</selfCollide>
      <material>Gazebo/Orange</material>
    </gazebo>
    <gazebo reference="${name}_arm_6_link">
      <turnGravityOff>false</turnGravityOff>
      <selfCollide>true</selfCollide>
      <material>Gazebo/Grey</material>
    </gazebo>
    <gazebo reference="${name}_arm_6_joint">
      <provideFeedback>true</provideFeedback>
    </gazebo>
    <gazebo reference="${name}_arm_7_link">
      <turnGravityOff>false</turnGravityOff>
      <selfCollide>true</selfCollide>
      <material>Gazebo/Grey</material>
    </gazebo>
    <!--
    <transmission name="${name}_arm_0_trans" type="SimpleTransmission">
      <actuator name="${name}_arm_0_motor" />
      <joint name="${name}_arm_0_joint" />
      <mechanicalReduction>1.0</mechanicalReduction>
    </transmission>
    <transmission name="${name}_arm_1_trans" type="SimpleTransmission">
      <actuator name="${name}_arm_1_motor" />
      <joint name="${name}_arm_1_joint" />
      <mechanicalReduction>1.0</mechanicalReduction>
    </transmission>
    <transmission name="${name}_arm_2_trans" type="SimpleTransmission">
      <actuator name="${name}_arm_2_motor" />
      <joint name="${name}_arm_2_joint" />
      <mechanicalReduction>1.0</mechanicalReduction>
    </transmission>
    <transmission name="${name}_arm_3_trans" type="SimpleTransmission">
      <actuator name="${name}_arm_3_motor" />
      <joint name="${name}_arm_3_joint" />
      <mechanicalReduction>1.0</mechanicalReduction>
    </transmission>
    <transmission name="${name}_arm_4_trans" type="SimpleTransmission">
      <actuator name="${name}_arm_4_motor" />
      <joint name="${name}_arm_4_joint" />
      <mechanicalReduction>1.0</mechanicalReduction>
    </transmission>
    <transmission name="${name}_arm_5_trans" type="SimpleTransmission">
      <actuator name="${name}_arm_5_motor" />
      <joint name="${name}_arm_5_joint" />
      <mechanicalReduction>1.0</mechanicalReduction>
    </transmission>
    <transmission name="${name}_arm_6_trans" type="SimpleTransmission">
      <actuator name="${name}_arm_6_motor" />
      <joint name="${name}_arm_6_joint" />
      <mechanicalReduction>1.0</mechanicalReduction>
    </transmission>
  -->
  </xacro:macro>
</robot>
